2019-02-25 23:43:06,729 ERROR: Exception on /search [GET] [in c:\microblog\venv\lib\site-packages\flask\app.py:1761]
Traceback (most recent call last):
  File "c:\microblog\venv\lib\site-packages\flask\app.py", line 2292, in wsgi_app
    response = self.full_dispatch_request()
  File "c:\microblog\venv\lib\site-packages\flask\app.py", line 1815, in full_dispatch_request
    rv = self.handle_user_exception(e)
  File "c:\microblog\venv\lib\site-packages\flask\app.py", line 1718, in handle_user_exception
    reraise(exc_type, exc_value, tb)
  File "c:\microblog\venv\lib\site-packages\flask\_compat.py", line 35, in reraise
    raise value
  File "c:\microblog\venv\lib\site-packages\flask\app.py", line 1813, in full_dispatch_request
    rv = self.dispatch_request()
  File "c:\microblog\venv\lib\site-packages\flask\app.py", line 1799, in dispatch_request
    return self.view_functions[rule.endpoint](**req.view_args)
  File "c:\microblog\venv\lib\site-packages\flask_login\utils.py", line 261, in decorated_view
    return func(*args, **kwargs)
  File "C:\microblog\app\main\routes.py", line 145, in search
    posts, total = Post.search(g.search_form.q.data, page, current_app.config['POSTS_PER_PAGE'])
  File "C:\microblog\app\models.py", line 95, in search
    ids, total = query_index(cls.__tablename__, expression, page, per_page)
  File "C:\microblog\app\search.py", line 26, in query_index
    'from': (page - 1) * per_page, 'size': per_page})
  File "c:\microblog\venv\lib\site-packages\elasticsearch\client\utils.py", line 76, in _wrapped
    return func(*args, params=params, **kwargs)
  File "c:\microblog\venv\lib\site-packages\elasticsearch\client\__init__.py", line 660, in search
    doc_type, '_search'), params=params, body=body)
  File "c:\microblog\venv\lib\site-packages\elasticsearch\transport.py", line 318, in perform_request
    status, headers_response, data = connection.perform_request(method, url, params, body, headers=headers, ignore=ignore, timeout=timeout)
  File "c:\microblog\venv\lib\site-packages\elasticsearch\connection\http_urllib3.py", line 186, in perform_request
    self._raise_error(response.status, raw_data)
  File "c:\microblog\venv\lib\site-packages\elasticsearch\connection\base.py", line 125, in _raise_error
    raise HTTP_EXCEPTIONS.get(status_code, TransportError)(status_code, error_message, additional_info)
elasticsearch.exceptions.RequestError: RequestError(400, 'search_phase_execution_exception', 'failed to create query: {\n  "multi_match" : {\n    "query" : "test",\n    "fields" : [\n      "*^1.0"\n    ],\n    "type" : "best_fields",\n    "operator" : "OR",\n    "slop" : 0,\n    "prefix_length" : 0,\n    "max_expansions" : 50,\n    "zero_terms_query" : "NONE",\n    "auto_generate_synonyms_phrase_query" : true,\n    "fuzzy_transpositions" : true,\n    "boost" : 1.0\n  }\n}')
2019-02-25 23:43:54,437 INFO: Microblog startup [in C:\microblog\app\__init__.py:79]
2019-02-26 00:22:37,406 INFO: Microblog startup [in C:\microblog\app\__init__.py:79]
2019-02-26 00:39:29,455 INFO: Microblog startup [in C:\microblog\app\__init__.py:79]
2019-02-26 00:43:04,603 INFO: Microblog startup [in C:\microblog\app\__init__.py:79]
2019-02-26 00:54:47,309 INFO: Microblog startup [in C:\microblog\app\__init__.py:79]
2019-02-26 00:57:34,743 INFO: Microblog startup [in C:\microblog\app\__init__.py:79]
2019-02-26 00:59:18,760 INFO: Microblog startup [in C:\microblog\app\__init__.py:79]
2019-02-26 00:59:41,991 INFO: Microblog startup [in C:\microblog\app\__init__.py:79]
2019-02-26 01:00:09,124 INFO: Microblog startup [in C:\microblog\app\__init__.py:79]
2019-02-26 01:01:33,319 INFO: Microblog startup [in C:\microblog\app\__init__.py:79]
2019-02-26 01:02:56,543 INFO: Microblog startup [in C:\microblog\app\__init__.py:79]
2019-02-26 01:04:19,474 INFO: Microblog startup [in C:\microblog\app\__init__.py:79]
2019-02-26 01:07:18,325 INFO: Microblog startup [in C:\microblog\app\__init__.py:79]
2019-03-07 18:01:51,386 INFO: Microblog startup [in C:\microblog\app\__init__.py:84]
2019-03-07 18:02:39,809 ERROR: Exception on / [POST] [in c:\microblog\venv\lib\site-packages\flask\app.py:1761]
Traceback (most recent call last):
  File "c:\microblog\venv\lib\site-packages\flask\app.py", line 2292, in wsgi_app
    response = self.full_dispatch_request()
  File "c:\microblog\venv\lib\site-packages\flask\app.py", line 1815, in full_dispatch_request
    rv = self.handle_user_exception(e)
  File "c:\microblog\venv\lib\site-packages\flask\app.py", line 1718, in handle_user_exception
    reraise(exc_type, exc_value, tb)
  File "c:\microblog\venv\lib\site-packages\flask\_compat.py", line 35, in reraise
    raise value
  File "c:\microblog\venv\lib\site-packages\flask\app.py", line 1813, in full_dispatch_request
    rv = self.dispatch_request()
  File "c:\microblog\venv\lib\site-packages\flask\app.py", line 1799, in dispatch_request
    return self.view_functions[rule.endpoint](**req.view_args)
  File "c:\microblog\venv\lib\site-packages\flask_login\utils.py", line 261, in decorated_view
    return func(*args, **kwargs)
  File "C:\microblog\app\main\routes.py", line 32, in index
    translate_client = translate.Client()
  File "c:\microblog\venv\lib\site-packages\google\cloud\translate_v2\client.py", line 64, in __init__
    super(Client, self).__init__(credentials=credentials, _http=_http)
  File "c:\microblog\venv\lib\site-packages\google\cloud\client.py", line 130, in __init__
    credentials, _ = google.auth.default()
  File "c:\microblog\venv\lib\site-packages\google\auth\_default.py", line 294, in default
    credentials, project_id = checker()
  File "c:\microblog\venv\lib\site-packages\google\auth\_default.py", line 165, in _get_explicit_environ_credentials
    os.environ[environment_vars.CREDENTIALS])
  File "c:\microblog\venv\lib\site-packages\google\auth\_default.py", line 89, in _load_credentials_from_file
    'File {} was not found.'.format(filename))
google.auth.exceptions.DefaultCredentialsError: File microblog-53e8b5e2a8f3.json was not found.
